<?xml version="1.0"?>
<robot xmlns:xacro="http://www.ros.org/wiki/xacro" name="mobile_robot">

  <!-- Base du robot -->
  <link name="base_link">
    <inertial>
      <mass value="5.0"/>
      <inertia ixx="0.1" iyy="0.1" izz="0.1" ixy="0.0" ixz="0.0" iyz="0.0"/>
    </inertial>
    <visual>
      <geometry>
        <box size="0.6 0.4 0.2"/>
      </geometry>
      <material name="green"/>
    </visual>
    <collision>
      <geometry>
        <box size="0.6 0.4 0.2"/>
      </geometry>
    </collision>
  </link>

  <!-- LIDAR -->
  <link name="lidar_link">
    <visual>
      <geometry>
        <cylinder radius="0.04" length="0.02"/>
      </geometry>
      <material name="gray"/>
    </visual>
    <collision>
      <geometry>
        <cylinder radius="0.04" length="0.02"/>
      </geometry>
    </collision>
  </link>

  <joint name="lidar_joint" type="fixed">
    <parent link="base_link"/>
    <child link="lidar_link"/>
    <origin xyz="0 0 0.15" rpy="0 0 0"/>
  </joint>

  <!-- Plugin LIDAR Gazebo -->
  <gazebo reference="lidar_link">
    <sensor type="ray" name="lidar_sensor">
      <update_rate>20</update_rate>
      <ray>
        <scan>
          <horizontal>
            <samples>720</samples>
            <resolution>1</resolution>
            <min_angle>-1.5708</min_angle>
            <max_angle>1.5708</max_angle>
          </horizontal>
        </scan>
        <range>
          <min>0.12</min>
          <max>12.0</max>
          <resolution>0.01</resolution>
        </range>
      </ray>
      <plugin name="gazebo_ros_lidar" filename="libgazebo_ros_ray_sensor.so">
        <ros>
          <namespace>/</namespace>
          <remapping>scan:=/scan</remapping>
        </ros>
      </plugin>
    </sensor>
  </gazebo>

  <!-- Roues (exemple roue avant gauche) -->
  <link name="front_left_wheel">
    <visual>
      <geometry>
        <cylinder radius="0.05" length="0.02"/>
      </geometry>
      <material name="black"/>
    </visual>
    <collision>
      <geometry>
        <cylinder radius="0.05" length="0.02"/>
      </geometry>
    </collision>
  </link>
  <joint name="front_left_wheel_joint" type="revolute">
    <parent link="base_link"/>
    <child link="front_left_wheel"/>
    <origin xyz="0.15 0.2 0" rpy="0 0 0"/>
    <axis xyz="0 0 1"/>
  </joint>

  <!-- Ajouter les autres roues de la même manière -->

</robot>

